# 异常处理(Exception)

在Lua中，我们通常会面对两种错误：预期的和非预期的。我们代码中使用`error`抛出的错误就是预期错误，用于通知调用者。而`prnit(123)`这样的拼写错误，是我们非预期的。

对于非预期错误而言，Lua的报错信息足够我们定位到它，并且直接进行修复。但预期错误，通常将错误定位在`error`调用的位置，而是实际代码被使用的位置，例如`__Arguments__`抛出的错误，会定位在函数被调用位置。这样开发者才能最快的找到错误点，进行修复。

但通常，定位错误点并不是容易的事情，我们通过`error(msg, stack)`指定stack level的方式，来指定实际错误点，之前介绍各个类型提供的反射API中，有大量的API可以传入stack level，也是为了便于计算抛出错误位置。

但很多情况下，定位stack level是比较困难的，例如一个函数如果使用`__Arguments__`, `__Async__`, `__Return__`同时封装，因为特性之间完全独立，推导stack level并不容易，而例如类的构造体中，如果抛出错误的话，因为存在继承，子类调用父类构造体方法等处理，stack level是完全无法确定的。

例如 :

```lua
require "PLoop" (function(_ENV)
	class "A" {
		function (self)
			error("Something error", 5)
		end
	}

	o = A()
end)
```

数字5可以通过测试找出，但当我们继承这个类时：

```lua
require "PLoop" (function(_ENV)
	class "A" {
		function (self)
			error("Something error", 5)
		end
	}

	class "B" (function(_ENV)
		inherit "A"

		function B(self)
			super(self)
		end
	end)

	o = B()
end)
```

这个stack level就完全不正确了。

但另一方面来说，这种情况只针对预期错误，非预期错误我们本来就希望直接定位。而预期错误是我们发起，实际是完全受控的。Lua中，并非只能用`error`抛出字符串，如果使用`pcall`调用处理，可以用table作为错误消息，这样我们可以在table中记录足够的信息，通常`pcall`在最外层使用，它捕获错误信息后，就可以在正确的调用位置，抛出错误了。


## System.Exception & throw

`System.Exception`对象封装了错误信息，所有异常类型都需要继承它，不过，目前**PLoop**仅提供了两个异常类型，另一个是用于单元测试的`System.UnitTest.TestFailureException`，后面的章节会介绍。

`Exception`类提供了以下的属性：

属性                 |描述
:--------------------|:--------------------------------
Message              |用于描述异常内容的字符串
StackTrace           |使用debug.traceback读取到的堆栈信息
TargetSite           |抛出错误信息的函数，依赖debug.info
Source               |抛出错误的位置，依赖debug.info
InnerException       |导致该异常的内部异常对象，一般捕获异常后，可以再抛出新的异常对象，不过目前不提供大量异常类型，这个属性暂时无用
Data                 |含有键值对，提供更多关于异常的信息，需要自行填入数据
LocalVariables       |含有键值对，对应抛出错误时函数的局部变量
Upvalues             |含有键值对，对应抛出错误时函数的闭包
StackDataSaved       |是否已经保存了堆栈数据，如果没保存，系统会尝试自行保存堆栈信息数据，如果通过平台设置调整为默认true，则系统不会尝试保存堆栈数据
StackLevel           |将被扫描的堆栈等级，默认1，即当前调用函数
SaveVariables        |是否保存局部变量和闭包，默认false

`Exception`类的构造：

```lua
__Arguments__{ String, Exception/nil, Boolean/nil }
function Exception(self, message, inner, savevariables)
    self.Message        = message
    self.InnerException = inner
    self.SaveVariables  = savevariables
end
```

通常，我们仅需要传入错误信息即可，其他数据会在使用`throw`关键字抛出异常对象时，自动填入：

```lua
require "PLoop" (function(_ENV)
	function test(a)
		local v = 2
		throw(Exception("Something error", nil, true))
	end

	local ok, exp = pcall(test, 1)

	-- Something error
	print(exp.StackTrace:match("^[^\n]*"))

	-- xxxx.lua:4
	print(exp.Source)

	-- a	1
	-- v	2
	for k, v in pairs(exp.LocalVariables) do
		print(k, v)
	end
end)
```

如果我们只想抛出错误，可以用`throw`直接抛出错误字符串，它会自行构建出异常对象：

```lua
require "PLoop" (function(_ENV)
	class "A" (function(_ENV)
		function A(self)
			throw("Something error")
		end
	end)

	-- xxxx.lua:9: Something error
	o = A()
end)
```

对象构造时，无论继承了多少层，使用`throw`抛出异常后，因为系统管理着对象的生成过程，所以，可以很方便的定位在对象被构造的位置。

另外，如果希望所有异常对象自动保存局部变量和闭包，可以通过平台配置开启`EXCEPTION_SAVE_VARIABLES`:

```lua
PLOOP_PLATFORM_SETTINGS = { EXCEPTION_SAVE_VARIABLES = true }
require "PLoop" (function(_ENV)
	function test(a)
		local v = 2
		throw("Something error")
	end

	local ok, exp = pcall(test, 1)

	-- Something error
	print(exp.StackTrace:match("^[^\n]*"))

	-- xxxx.lua:4
	print(exp.Source)

	-- a	1
	-- v	2
	for k, v in pairs(exp.LocalVariables) do
		print(k, v)
	end
end)
```

**PLoop**系统中，`throw`已被对象构造，`__Arguments__`参数验证，属性（设置了`throw=true`）这些场景处理掉。其他时候，需要自行处理。


## Support throw

处理异常只需要使用`pcall`，然后判定下错误消息的类型即可，`throw`关键字可以在任何**PLoop**环境中被使用。

```lua
require "PLoop" (function(_ENV)
	function task()
		throw("Something error")
	end

	function test()
		local ok, ret = pcall(task)

		if not ok then
			if type(ret) == "string" then
				error(ret, 0)           -- 非预期错误，使用0保证它的定位在原位置
			else
				error(tostring(ret), 2) -- 预期错误，2代表了test函数被调用的位置
			end
		end
	end

	-- xxxx.lua:19: Something error
	test()
end)
```


## `__Arguments__` & throw

`__Arguments__`对函数的封装较为复杂，特别如果作为重载用途，stack level相对要复杂，如果期望用`throw`抛出错误，那么我们需要通知`__Arguments__`特性：

```lua
require "PLoop" (function(_ENV)
	__Arguments__{ Number }:Throwable()
	function div(num)
		if num == 0 then
			throw("zero is not allowed")
		end
	end

	-- xxxx.lua:10: zero is not allowed
	div(0)
end)
```

通过实用`Throwable`方法，特性可以确认自己要调用的处理，可能抛出异常对象，它会针对这种情况做出处理，将抛出的异常定位在调用位置。


## Property & throw

属性配置后，系统会根据配置情况自行生成优化的访问代码，但也会造成，抛出错误的堆栈级别无法固定，为了使用`throw`抛出错误，也需要在属性定义时注明：

```lua
require "PLoop" (function(_ENV)
	class "Person" (function(_ENV)
		field { __name = "anonymous" }

		function SetName(self, name)
			if type(name) ~= "string" then
				throw("The name must be string")
			end
			self.__name = name
		end

		function GetName(self)
			return self.__name
		end

		property "Name" {
			get = "GetName", -- or getmethod = "GetName"
			set = "SetName", -- or setmethod = "SetName"
			throwable = true,
		}
	end)

	-- xxxx.lua:24: The name must be string
	Person().Name = 123
end)
```